<?xml version="1.0" ?>
<robot name="urdf_simplified" xmlns:xacro="http://www.ros.org/wiki/xacro">

<xacro:include filename="$(find urdf_simplified_description)/urdf/materials.xacro" />
<xacro:include filename="$(find urdf_simplified_description)/urdf/urdf_simplified.trans" />
<xacro:include filename="$(find urdf_simplified_description)/urdf/urdf_simplified.gazebo" />
<link name="world">
  <visual>
  <origin rpy="0 0 0" xyz="0 0 0" />
    <geometry>
       <box size="0.000008 0.000008 0.000003"/>
    </geometry>
  </visual>
</link>
<link name="base_link">
    <inertial>
    <origin xyz="-5.700880775444023e-15 -2.3388228822334454e-17 -0.008539058485288596" rpy="0 0 0"/>
    <mass value="0.05152508507605951"/>
    <inertia ixx="6.5e-05" iyy="6.5e-05" izz="0.000121" ixy="-0.0" iyz="-0.0" ixz="0.0"/>
  </inertial>
  <visual>
    <origin xyz="0 0 0" rpy="0 0 0"/>
    <geometry>
      <mesh filename="package://urdf_simplified_description/meshes/base_link.stl" scale="0.001 0.001 0.001"/>
    </geometry>
    <material name="silver"/>
  </visual>
  <collision>
    <origin xyz="0 0 0" rpy="0 0 0"/>
    <geometry>
      <mesh filename="package://urdf_simplified_description/meshes/base_link.stl" scale="0.001 0.001 0.001"/>
    </geometry>
  </collision>
</link>

<link name="Component2_1">
  <inertial>
    <origin xyz="6.754288398751157e-10 8.062612255736307e-08 0.022293335424730373" rpy="0 0 0"/>
    <mass value="0.04301828993424946"/>
    <inertia ixx="3.8e-05" iyy="4e-05" izz="6.6e-05" ixy="0.0" iyz="-0.0" ixz="-0.0"/>
  </inertial>
  <visual>
    <origin xyz="-0.0 -0.0 -0.002" rpy="0 0 0"/>
    <geometry>
      <mesh filename="package://urdf_simplified_description/meshes/Component2_1.stl" scale="0.001 0.001 0.001"/>
    </geometry>
    <material name="silver"/>
  </visual>
  <collision>
    <origin xyz="-0.0 -0.0 -0.002" rpy="0 0 0"/>
    <geometry>
      <mesh filename="package://urdf_simplified_description/meshes/Component2_1.stl" scale="0.001 0.001 0.001"/>
    </geometry>
  </collision>
</link>

<link name="Component3_1">
  <inertial>
    <origin xyz="-0.026 0.016858904245414866 0.029830953320340817" rpy="0 0 0"/>
    <mass value="0.07759761667831801"/>
    <inertia ixx="4.1e-05" iyy="4.5e-05" izz="2.4e-05" ixy="-0.0" iyz="-2e-06" ixz="-0.0"/>
  </inertial>
  <visual>
    <origin xyz="-0.025 -0.0 -0.049" rpy="0 0 0"/>
    <geometry>
      <mesh filename="package://urdf_simplified_description/meshes/Component3_1.stl" scale="0.001 0.001 0.001"/>
    </geometry>
    <material name="silver"/>
  </visual>
  <collision>
    <origin xyz="-0.025 -0.0 -0.049" rpy="0 0 0"/>
    <geometry>
      <mesh filename="package://urdf_simplified_description/meshes/Component3_1.stl" scale="0.001 0.001 0.001"/>
    </geometry>
  </collision>
</link>

<link name="Component4_1">
  <inertial>
    <origin xyz="-0.021515666357247706 -0.022058729538877265 -3.5313233675560163e-06" rpy="0 0 0"/>
    <mass value="0.015212282444311782"/>
    <inertia ixx="1.9e-05" iyy="1.2e-05" izz="3e-05" ixy="0.0" iyz="-0.0" ixz="0.0"/>
  </inertial>
  <visual>
    <origin xyz="-0.021 -0.01 -0.134" rpy="0 0 0"/>
    <geometry>
      <mesh filename="package://urdf_simplified_description/meshes/Component4_1.stl" scale="0.001 0.001 0.001"/>
    </geometry>
    <material name="silver"/>
  </visual>
  <collision>
    <origin xyz="-0.021 -0.01 -0.134" rpy="0 0 0"/>
    <geometry>
      <mesh filename="package://urdf_simplified_description/meshes/Component4_1.stl" scale="0.001 0.001 0.001"/>
    </geometry>
  </collision>
</link>

<link name="Component5_1">
  <inertial>
    <origin xyz="0.031149448590471997 -0.01645251032308831 0.0003726711981377473" rpy="0 0 0"/>
    <mass value="0.008845043566948384"/>
    <inertia ixx="3e-06" iyy="4e-06" izz="6e-06" ixy="-0.0" iyz="-0.0" ixz="0.0"/>
  </inertial>
  <visual>
    <origin xyz="0.03 0.065 -0.133991" rpy="0 0 0"/>
    <geometry>
      <mesh filename="package://urdf_simplified_description/meshes/Component5_1.stl" scale="0.001 0.001 0.001"/>
    </geometry>
    <material name="silver"/>
  </visual>
  <collision>
    <origin xyz="0.03 0.065 -0.133991" rpy="0 0 0"/>
    <geometry>
      <mesh filename="package://urdf_simplified_description/meshes/Component5_1.stl" scale="0.001 0.001 0.001"/>
    </geometry>
  </collision>
</link>

<joint name="base_link__link" type="fixed">
    <axis xyz="0 0 1"/>
    <origin rpy="0 0 0" xyz="0 0 0.3"/>
    <parent link="world"/>
    <child link="base_link"/>
 </joint>  
<joint name="Revolute 1" type="revolute">
  <origin xyz="0.0 0.0 0.002" rpy="0 0 0"/>
  <limit effort="10.0" lower="-3.14" upper="3.14" velocity="0.0"/>
  <parent link="base_link"/>
  <child link="Component2_1"/>
  <axis xyz="0.0 0.0 -1.0"/>
</joint>

<joint name="Revolute 2" type="revolute">
  <origin xyz="0.025 0.0 0.047" rpy="0 0 0"/>
  <limit effort="10.0" lower="-3.14" upper="3.14" velocity="0.0"/>
  <parent link="Component2_1"/>
  <child link="Component3_1"/>
  <axis xyz="1.0 0.0 0.0"/>
</joint>

<joint name="Revolute 3" type="revolute">
  <origin xyz="-0.004 0.01 0.085" rpy="0 0 0"/>
  <limit effort="10.0" lower="-3.14" upper="3.14" velocity="0.0"/>
  <parent link="Component3_1"/>
  <child link="Component4_1"/>
  <axis xyz="-1.0 0.0 0.0"/>
</joint>

<joint name="Revolute 4" type="revolute">
  <origin xyz="-0.051 -0.075 -9e-06" rpy="0 0 0"/>
  <limit effort="10.0" lower="-3.14" upper="3.14" velocity="0.0"/>
  <parent link="Component4_1"/>
  <child link="Component5_1"/>
  <axis xyz="-1.0 0.0 0.0"/>
</joint>

</robot>
