<?xml version="1.0"?>
<robot name="kaju">
    <link name="world">
        <visual>
          <origin rpy="0 0 0" xyz="0 0 0.15" />
          <geometry>
            <box size="0.8 0.8 0.3"/>
          </geometry>
        </visual>
    </link>
    <link name="base">     
        <inertial>
            <origin rpy="0 0 0" xyz="0 0 0.1"/>
            <mass value="3"/>
            <inertia ixx="0.0075"  ixy="0"  ixz="0" iyy="0.0075" iyz="0" izz="0.135" />
        </inertial>   
        <visual>
          <origin rpy="0 0 0" xyz="0 0 0.1" />
          <geometry>
            <cylinder radius="0.3" length="0.2" />
          </geometry>
        </visual>
        <collision>
            <origin rpy="0 0 0" xyz="0 0 0.1" />
            <geometry>
                <cylinder radius="0.3" length="0.2" />
            </geometry>
        </collision>
    </link>
    <link name="my_link_1">  
        <inertial>
            <origin rpy="0 0 0" xyz="0 0 0.3"/>
            <mass value="2"/>
            <inertia ixx="0.075"  ixy="0"  ixz="0" iyy="0.03" iyz="0" izz="0.075" />
        </inertial>     
        <visual>
          <origin rpy="0 0 0" xyz="0 0 0.3" />
          <geometry>
            <box size="0.3 0.3 0.6"/>
          </geometry>
        </visual>
        <collision>
          <origin rpy="0 0 0" xyz="0 0 0.3" />
          <geometry>
            <box size="0.3 0.3 0.6"/>
          </geometry>      
        </collision>
    </link>
    <link name="my_link_2">
        <inertial>
            <origin rpy="0 0 0" xyz="0 0 0.25"/>
            <mass value="1"/>
            <inertia ixx="0.0342"  ixy="0"  ixz="0" iyy="0.0267" iyz="0" izz="0.0342" />
        </inertial>  
        <visual>
            <origin rpy="0 0 0" xyz="0 0 0.25" />
            <geometry>
             <box size="0.4 0.4 0.5"/>
            </geometry>
        </visual>
        <collision>
            <origin rpy="0 0 0" xyz="0 0 0.25" />
            <geometry>
             <box size="0.4 0.4 0.5"/>
            </geometry>       
        </collision>
    </link>
    <link name="my_link_3">
        <inertial>
            <origin rpy="0 0 0" xyz="0 0 0.1"/>
            <mass value="1"/>
            <inertia ixx="0.0108"  ixy="0"  ixz="0" iyy="0.015" iyz="0" izz="0.0108" />
        </inertial>  
        <visual>
            <origin rpy="0 0 0" xyz="0 0 0.1" />
            <geometry>
             <box size="0.3 0.3 0.2"/>
            </geometry>
        </visual>
        <collision>
            <origin rpy="0 0 0" xyz="0 0 0.1" />
            <geometry>
             <box size="0.3 0.3 0.2"/>
            </geometry>      
        </collision>
    </link>

    <joint name="base_link__link" type="revolute">
        <axis xyz="0 0 1"/>
        <limit effort="1000.0" lower="-3.14" upper="3.14" velocity="0.5"/>
        <origin rpy="0 0 0" xyz="0 0 0.3"/>
        <parent link="world"/>
        <child link="base"/>
    </joint>    
    <joint name="base_link__link_00" type="revolute">
        <axis xyz="0 1 0"/>
        <limit effort="1000.0" lower="-3.14" upper="3.14" velocity="0.5"/>
        <origin rpy="0 0 0" xyz="0 0 0.2"/>
        <parent link="base"/>
        <child link="my_link_1"/>
    </joint>
    <joint name="base_link__link_01" type="revolute">
        <axis xyz="0 1 0"/>
        <limit effort="1000.0" lower="-1.57" upper="1.57" velocity="0.5"/>
        <origin rpy="0 0 0" xyz="0 0 0.6"/>
        <parent link="my_link_1"/>
        <child link="my_link_2"/>
    </joint>
    <joint name="base_link__link_02" type="revolute">
        <axis xyz="0 1 0"/>
        <limit effort="1000.0" lower="-1.57" upper="1.57" velocity="0.5"/>
        <origin rpy="0 0 0" xyz="0 0 0.5"/>
        <parent link="my_link_2"/>
        <child link="my_link_3"/>
    </joint>

    <transmission name="Trans-0">
        <type>transmission_interface/SimpleTransmission</type>
        <joint name="base_link__link">
          <hardwareInterface>hardware_interface/PositionJointInterface</hardwareInterface>
        </joint>
        <actuator name="motor-0">
          <mechanicalReduction>1</mechanicalReduction>
          <hardwareInterface>hardware_interface/PositionJointInterface</hardwareInterface>
        </actuator>
    </transmission>
    <transmission name="Trans-1">
        <type>transmission_interface/SimpleTransmission</type>
        <joint name="base_link__link_00">
          <hardwareInterface>hardware_interface/PositionJointInterface</hardwareInterface>
        </joint>
        <actuator name="motor-1">
          <mechanicalReduction>1</mechanicalReduction>
          <hardwareInterface>hardware_interface/PositionJointInterface</hardwareInterface>
        </actuator>
    </transmission>
    <transmission name="Trans-2">
        <type>transmission_interface/SimpleTransmission</type>
        <joint name="base_link__link_01">
          <hardwareInterface>hardware_interface/PositionJointInterface</hardwareInterface>
        </joint>
        <actuator name="motor-2">
          <mechanicalReduction>1</mechanicalReduction>
          <hardwareInterface>hardware_interface/PositionJointInterface</hardwareInterface>
        </actuator>
    </transmission>
    <transmission name="Trans-3">
        <type>transmission_interface/SimpleTransmission</type>
        <joint name="base_link__link_02">
          <hardwareInterface>hardware_interface/PositionJointInterface</hardwareInterface>
        </joint>
        <actuator name="motor-2">
          <mechanicalReduction>1</mechanicalReduction>
          <hardwareInterface>hardware_interface/PositionJointInterface</hardwareInterface>
        </actuator>
    </transmission>

    <gazebo>
        <plugin name="control" filename="libgazebo_ros_control.so"/>
    </gazebo>
</robot>